
import asyncio
import logging
from functools import wraps
from datetime import datetime, timedelta

# Configure logging
logging.basicConfig(level=logging.ERROR, format="%(asctime)s - %(levelname)s - %(message)s"))

class CircuitBreaker:
    def __init__(self, failure_threshold=5, recovery_timeout=30, expected_exception=Exception):
        self.failure_threshold = failure_threshold
        self.recovery_timeout = recovery_timeout
        self.expected_exception = expected_exception
        self.failures = 0
        self.last_failure_time = None
        self.is_open = False

    def __call__(self, func):
        @wraps(func)
        async def wrapper(*args, **kwargs):
            if self.is_open:
                if datetime.now() > self.last_failure_time + timedelta(seconds=self.recovery_timeout):
                    # Attempt to half-open
                    self.is_open = False
                    self.failures = 0
                else:
                    raise CircuitBreakerOpenException("Circuit breaker is open")

            try:
                result = await func(*args, **kwargs)
                self.failures = 0  # Reset failures on success
                return result
            except self.expected_exception as e:
                self.failures += 1
                self.last_failure_time = datetime.now()
                if self.failures >= self.failure_threshold:
                    self.is_open = True
                    logging.error(f"Circuit breaker opened for {func.__name__} due to excessive failures.")
                raise
        return wrapper

class CircuitBreakerOpenException(Exception):
    pass

def with_retry(max_retries=3, delay=1, backoff=2, expected_exception=Exception):
    def decorator(func):
        @wraps(func)
        async def wrapper(*args, **kwargs):
            retries = 0
            current_delay = delay
            while retries < max_retries:
                try:
                    return await func(*args, **kwargs)
                except expected_exception as e:
                    logging.warning(f"Attempt {retries + 1} failed for {func.__name__}: {e}")
                    retries += 1
                    if retries < max_retries:
                        await asyncio.sleep(current_delay)
                        current_delay *= backoff
            raise ConnectionError(f"Max retries exceeded for {func.__name__}")
        return wrapper
    return decorator

def with_error_handling(fallback=None):
    def decorator(func):
        @wraps(func)
        async def wrapper(*args, **kwargs):
            try:
                return await func(*args, **kwargs)
            except Exception as e:
                logging.error(f"Error in {func.__name__}: {e}")
                # In a real scenario, this would log to a database
                # For now, we'll just print a placeholder.
                print(f"DATABASE LOG: Error in {func.__name__}: {e}")
                if fallback:
                    if asyncio.iscoroutinefunction(fallback):
                        return await fallback(*args, **kwargs)
                    else:
                        return fallback(*args, **kwargs)
                raise
        return wrapper
    return decorator

# Placeholder for database logging (to be implemented)
async def log_error_to_db(error_message, module, function_name):
    print(f"Logging error to DB: {{'timestamp': datetime.now(), 'module': module, 'function': function_name, 'message': error_message}}")

# Example fallback function
async def default_fallback_value(*args, **kwargs):
    logging.info("Executing default fallback function.")
    return None

